Workbook

Sheet travel_time
B1: 0 | C1: 1 | D1: 2 | E1: 3 | F1: 4 | G1: 5 | H1: 6
A2: 0 | B2: 0 | C2: 13 | D2: 24 | E2: 20 | F2: 15 | G2: 20 | H2: 13
A3: 1 | B3: 13 | C3: 0 | D3: 29 | E3: 32 | F3: 22 | G3: 27 | H3: 22
A4: 2 | B4: 24 | C4: 29 | D4: 0 | E4: 46 | F4: 22 | G4: 20 | H4: 32
A5: 3 | B5: 20 | C5: 32 | D5: 46 | E5: 0 | F5: 25 | G5: 29 | H5: 15
A6: 4 | B6: 15 | C6: 22 | D6: 22 | E6: 25 | F6: 0 | G6: 5 | H6: 10
A7: 5 | B7: 20 | C7: 27 | D7: 20 | E7: 29 | F7: 5 | G7: 0 | H7: 15
A8: 6 | B8: 13 | C8: 22 | D8: 32 | E8: 15 | F8: 10 | G8: 15 | H8: 0

Sheet burned_area
B1: 1 | C1: 2 | D1: 3 | E1: 4 | F1: 5 | G1: 6
A2: 1 | B2: 48497.423 | C2: 6928.2032 | D2: 34641.016 | E2: 6928.2032 | F2: 6928.2032 | G2: 48497.423
A3: 2 | B3: =(B$11-B$2)/(100)*$A3+B$2 -> 49883.063 | C3: =(C$11-C$2)/(100)*$A3+C$2 -> 7066.7673 | D3: =(D$11-D$2)/(100)*$A3+D$2 -> 35195.272 | E3: =(E$11-E$2)/(100)*$A3+E$2 -> 7759.5876 | F3: =(F$11-F$2)/(100)*$A3+F$2 -> 6928.2032 | G3: =(G$11-G$2)/(100)*$A3+G$2 -> 49744.499
A4: 3 | B4: =(B$11-B$2)/(100)*$A4+B$2 -> 50575.884 | C4: =(C$11-C$2)/(100)*$A4+C$2 -> 7136.0493 | D4: =(D$11-D$2)/(100)*$A4+D$2 -> 35472.401 | E4: =(E$11-E$2)/(100)*$A4+E$2 -> 8175.2798 | F4: =(F$11-F$2)/(100)*$A4+F$2 -> 6928.2032 | G4: =(G$11-G$2)/(100)*$A4+G$2 -> 50368.037
A5: 4 | B5: =(B$11-B$2)/(100)*$A5+B$2 -> 51268.704 | C5: =(C$11-C$2)/(100)*$A5+C$2 -> 7205.3314 | D5: =(D$11-D$2)/(100)*$A5+D$2 -> 35749.529 | E5: =(E$11-E$2)/(100)*$A5+E$2 -> 8590.972 | F5: =(F$11-F$2)/(100)*$A5+F$2 -> 6928.2032 | G5: =(G$11-G$2)/(100)*$A5+G$2 -> 50991.576
A6: 5 | B6: =(B$11-B$2)/(100)*$A6+B$2 -> 51961.524 | C6: =(C$11-C$2)/(100)*$A6+C$2 -> 7274.6134 | D6: =(D$11-D$2)/(100)*$A6+D$2 -> 36026.657 | E6: =(E$11-E$2)/(100)*$A6+E$2 -> 9006.6642 | F6: =(F$11-F$2)/(100)*$A6+F$2 -> 6928.2032 | G6: =(G$11-G$2)/(100)*$A6+G$2 -> 51615.114
A7: 6 | B7: =(B$11-B$2)/(100)*$A7+B$2 -> 52654.345 | C7: =(C$11-C$2)/(100)*$A7+C$2 -> 7343.8954 | D7: =(D$11-D$2)/(100)*$A7+D$2 -> 36303.785 | E7: =(E$11-E$2)/(100)*$A7+E$2 -> 9422.3564 | F7: =(F$11-F$2)/(100)*$A7+F$2 -> 6928.2032 | G7: =(G$11-G$2)/(100)*$A7+G$2 -> 52238.652
A8: 7 | B8: =(B$11-B$2)/(100)*$A8+B$2 -> 53347.165 | C8: =(C$11-C$2)/(100)*$A8+C$2 -> 7413.1775 | D8: =(D$11-D$2)/(100)*$A8+D$2 -> 36580.913 | E8: =(E$11-E$2)/(100)*$A8+E$2 -> 9838.0486 | F8: =(F$11-F$2)/(100)*$A8+F$2 -> 6928.2032 | G8: =(G$11-G$2)/(100)*$A8+G$2 -> 52862.191
A9: 8 | B9: =(B$11-B$2)/(100)*$A9+B$2 -> 54039.985 | C9: =(C$11-C$2)/(100)*$A9+C$2 -> 7482.4595 | D9: =(D$11-D$2)/(100)*$A9+D$2 -> 36858.041 | E9: =(E$11-E$2)/(100)*$A9+E$2 -> 10253.741 | F9: =(F$11-F$2)/(100)*$A9+F$2 -> 6928.2032 | G9: =(G$11-G$2)/(100)*$A9+G$2 -> 53485.729
A10: 9 | B10: =(B$11-B$2)/(100)*$A10+B$2 -> 54732.806 | C10: =(C$11-C$2)/(100)*$A10+C$2 -> 7551.7415 | D10: =(D$11-D$2)/(100)*$A10+D$2 -> 37135.169 | E10: =(E$11-E$2)/(100)*$A10+E$2 -> 10669.433 | F10: =(F$11-F$2)/(100)*$A10+F$2 -> 6928.2032 | G10: =(G$11-G$2)/(100)*$A10+G$2 -> 54109.267
A11: 10 | B11: 117779.45 | C11: 13856.406 | D11: 62353.829 | E11: 48497.423 | F11: 6928.2032 | G11: 110851.25
A12: 11 | B12: =(B$21-B$11)/(100)*($A12-$A$11)+B$11 -> 118541.56 | C12: =(C$21-C$11)/(100)*($A12-$A$11)+C$11 -> 14202.817 | D12: =(D$21-D$11)/(100)*($A12-$A$11)+D$11 -> 62769.521 | E12: =(E$21-E$11)/(100)*($A12-$A$11)+E$11 -> 49120.961 | F12: =(F$21-F$11)/(100)*($A12-$A$11)+F$11 -> 7066.7673 | G12: =(G$21-G$11)/(100)*($A12-$A$11)+G$11 -> 111474.79
A13: 12 | B13: =(B$21-B$11)/(100)*($A13-$A$11)+B$11 -> 119303.66 | C13: =(C$21-C$11)/(100)*($A13-$A$11)+C$11 -> 14549.227 | D13: =(D$21-D$11)/(100)*($A13-$A$11)+D$11 -> 63185.213 | E13: =(E$21-E$11)/(100)*($A13-$A$11)+E$11 -> 49744.499 | F13: =(F$21-F$11)/(100)*($A13-$A$11)+F$11 -> 7205.3314 | G13: =(G$21-G$11)/(100)*($A13-$A$11)+G$11 -> 112098.33
A14: 13 | B14: =(B$21-B$11)/(100)*($A14-$A$11)+B$11 -> 120065.76 | C14: =(C$21-C$11)/(100)*($A14-$A$11)+C$11 -> 14895.637 | D14: =(D$21-D$11)/(100)*($A14-$A$11)+D$11 -> 63600.906 | E14: =(E$21-E$11)/(100)*($A14-$A$11)+E$11 -> 50368.037 | F14: =(F$21-F$11)/(100)*($A14-$A$11)+F$11 -> 7343.8954 | G14: =(G$21-G$11)/(100)*($A14-$A$11)+G$11 -> 112721.87
A15: 14 | B15: =(B$21-B$11)/(100)*($A15-$A$11)+B$11 -> 120827.86 | C15: =(C$21-C$11)/(100)*($A15-$A$11)+C$11 -> 15242.047 | D15: =(D$21-D$11)/(100)*($A15-$A$11)+D$11 -> 64016.598 | E15: =(E$21-E$11)/(100)*($A15-$A$11)+E$11 -> 50991.576 | F15: =(F$21-F$11)/(100)*($A15-$A$11)+F$11 -> 7482.4595 | G15: =(G$21-G$11)/(100)*($A15-$A$11)+G$11 -> 113345.4
A16: 15 | B16: =(B$21-B$11)/(100)*($A16-$A$11)+B$11 -> 121589.97 | C16: =(C$21-C$11)/(100)*($A16-$A$11)+C$11 -> 15588.457 | D16: =(D$21-D$11)/(100)*($A16-$A$11)+D$11 -> 64432.29 | E16: =(E$21-E$11)/(100)*($A16-$A$11)+E$11 -> 51615.114 | F16: =(F$21-F$11)/(100)*($A16-$A$11)+F$11 -> 7621.0236 | G16: =(G$21-G$11)/(100)*($A16-$A$11)+G$11 -> 113968.94
A17: 16 | B17: =(B$21-B$11)/(100)*($A17-$A$11)+B$11 -> 122352.07 | C17: =(C$21-C$11)/(100)*($A17-$A$11)+C$11 -> 15934.867 | D17: =(D$21-D$11)/(100)*($A17-$A$11)+D$11 -> 64847.982 | E17: =(E$21-E$11)/(100)*($A17-$A$11)+E$11 -> 52238.652 | F17: =(F$21-F$11)/(100)*($A17-$A$11)+F$11 -> 7759.5876 | G17: =(G$21-G$11)/(100)*($A17-$A$11)+G$11 -> 114592.48
A18: 17 | B18: =(B$21-B$11)/(100)*($A18-$A$11)+B$11 -> 123114.17 | C18: =(C$21-C$11)/(100)*($A18-$A$11)+C$11 -> 16281.278 | D18: =(D$21-D$11)/(100)*($A18-$A$11)+D$11 -> 65263.674 | E18: =(E$21-E$11)/(100)*($A18-$A$11)+E$11 -> 52862.191 | F18: =(F$21-F$11)/(100)*($A18-$A$11)+F$11 -> 7898.1517 | G18: =(G$21-G$11)/(100)*($A18-$A$11)+G$11 -> 115216.02
A19: 18 | B19: =(B$21-B$11)/(100)*($A19-$A$11)+B$11 -> 123876.27 | C19: =(C$21-C$11)/(100)*($A19-$A$11)+C$11 -> 16627.688 | D19: =(D$21-D$11)/(100)*($A19-$A$11)+D$11 -> 65679.367 | E19: =(E$21-E$11)/(100)*($A19-$A$11)+E$11 -> 53485.729 | F19: =(F$21-F$11)/(100)*($A19-$A$11)+F$11 -> 8036.7157 | G19: =(G$21-G$11)/(100)*($A19-$A$11)+G$11 -> 115839.56
A20: 19 | B20: =(B$21-B$11)/(100)*($A20-$A$11)+B$11 -> 124638.38 | C20: =(C$21-C$11)/(100)*($A20-$A$11)+C$11 -> 16974.098 | D20: =(D$21-D$11)/(100)*($A20-$A$11)+D$11 -> 66095.059 | E20: =(E$21-E$11)/(100)*($A20-$A$11)+E$11 -> 54109.267 | F20: =(F$21-F$11)/(100)*($A20-$A$11)+F$11 -> 8175.2798 | G20: =(G$21-G$11)/(100)*($A20-$A$11)+G$11 -> 116463.1
A21: 20 | B21: 193989.69 | C21: 48497.423 | D21: 103923.05 | E21: 110851.25 | F21: 20784.61 | G21: 173205.08
A22: 21 | B22: =(B$31-B$21)/(100)*($A22-$A$21)+B$21 -> 194543.95 | C22: =(C$31-C$21)/(100)*($A22-$A$21)+C$21 -> 49120.961 | D22: =(D$31-D$21)/(100)*($A22-$A$21)+D$21 -> 104408.02 | E22: =(E$31-E$21)/(100)*($A22-$A$21)+E$21 -> 111682.64 | F22: =(F$31-F$21)/(100)*($A22-$A$21)+F$21 -> 21269.584 | G22: =(G$31-G$21)/(100)*($A22-$A$21)+G$21 -> 174036.47
A23: 22 | B23: =(B$31-B$21)/(100)*($A23-$A$21)+B$21 -> 195098.2 | C23: =(C$31-C$21)/(100)*($A23-$A$21)+C$21 -> 49744.499 | D23: =(D$31-D$21)/(100)*($A23-$A$21)+D$21 -> 104893 | E23: =(E$31-E$21)/(100)*($A23-$A$21)+E$21 -> 112514.02 | F23: =(F$31-F$21)/(100)*($A23-$A$21)+F$21 -> 21754.558 | G23: =(G$31-G$21)/(100)*($A23-$A$21)+G$21 -> 174867.85
A24: 23 | B24: =(B$31-B$21)/(100)*($A24-$A$21)+B$21 -> 195652.46 | C24: =(C$31-C$21)/(100)*($A24-$A$21)+C$21 -> 50368.037 | D24: =(D$31-D$21)/(100)*($A24-$A$21)+D$21 -> 105377.97 | E24: =(E$31-E$21)/(100)*($A24-$A$21)+E$21 -> 113345.4 | F24: =(F$31-F$21)/(100)*($A24-$A$21)+F$21 -> 22239.532 | G24: =(G$31-G$21)/(100)*($A24-$A$21)+G$21 -> 175699.23
A25: 24 | B25: =(B$31-B$21)/(100)*($A25-$A$21)+B$21 -> 196206.72 | C25: =(C$31-C$21)/(100)*($A25-$A$21)+C$21 -> 50991.576 | D25: =(D$31-D$21)/(100)*($A25-$A$21)+D$21 -> 105862.95 | E25: =(E$31-E$21)/(100)*($A25-$A$21)+E$21 -> 114176.79 | F25: =(F$31-F$21)/(100)*($A25-$A$21)+F$21 -> 22724.507 | G25: =(G$31-G$21)/(100)*($A25-$A$21)+G$21 -> 176530.62
A26: 25 | B26: =(B$31-B$21)/(100)*($A26-$A$21)+B$21 -> 196760.97 | C26: =(C$31-C$21)/(100)*($A26-$A$21)+C$21 -> 51615.114 | D26: =(D$31-D$21)/(100)*($A26-$A$21)+D$21 -> 106347.92 | E26: =(E$31-E$21)/(100)*($A26-$A$21)+E$21 -> 115008.17 | F26: =(F$31-F$21)/(100)*($A26-$A$21)+F$21 -> 23209.481 | G26: =(G$31-G$21)/(100)*($A26-$A$21)+G$21 -> 177362
A27: 26 | B27: =(B$31-B$21)/(100)*($A27-$A$21)+B$21 -> 197315.23 | C27: =(C$31-C$21)/(100)*($A27-$A$21)+C$21 -> 52238.652 | D27: =(D$31-D$21)/(100)*($A27-$A$21)+D$21 -> 106832.89 | E27: =(E$31-E$21)/(100)*($A27-$A$21)+E$21 -> 115839.56 | F27: =(F$31-F$21)/(100)*($A27-$A$21)+F$21 -> 23694.455 | G27: =(G$31-G$21)/(100)*($A27-$A$21)+G$21 -> 178193.39
A28: 27 | B28: =(B$31-B$21)/(100)*($A28-$A$21)+B$21 -> 197869.48 | C28: =(C$31-C$21)/(100)*($A28-$A$21)+C$21 -> 52862.191 | D28: =(D$31-D$21)/(100)*($A28-$A$21)+D$21 -> 107317.87 | E28: =(E$31-E$21)/(100)*($A28-$A$21)+E$21 -> 116670.94 | F28: =(F$31-F$21)/(100)*($A28-$A$21)+F$21 -> 24179.429 | G28: =(G$31-G$21)/(100)*($A28-$A$21)+G$21 -> 179024.77
A29: 28 | B29: =(B$31-B$21)/(100)*($A29-$A$21)+B$21 -> 198423.74 | C29: =(C$31-C$21)/(100)*($A29-$A$21)+C$21 -> 53485.729 | D29: =(D$31-D$21)/(100)*($A29-$A$21)+D$21 -> 107802.84 | E29: =(E$31-E$21)/(100)*($A29-$A$21)+E$21 -> 117502.33 | F29: =(F$31-F$21)/(100)*($A29-$A$21)+F$21 -> 24664.403 | G29: =(G$31-G$21)/(100)*($A29-$A$21)+G$21 -> 179856.16
A30: 29 | B30: =(B$31-B$21)/(100)*($A30-$A$21)+B$21 -> 198978 | C30: =(C$31-C$21)/(100)*($A30-$A$21)+C$21 -> 54109.267 | D30: =(D$31-D$21)/(100)*($A30-$A$21)+D$21 -> 108287.82 | E30: =(E$31-E$21)/(100)*($A30-$A$21)+E$21 -> 118333.71 | F30: =(F$31-F$21)/(100)*($A30-$A$21)+F$21 -> 25149.378 | G30: =(G$31-G$21)/(100)*($A30-$A$21)+G$21 -> 180687.54
A31: 30 | B31: 249415.32 | C31: 110851.25 | D31: 152420.47 | E31: 193989.69 | F31: 69282.032 | G31: 256343.52
A32: 31 | B32: =(B$41-B$31)/(100)*($A32-$A$31)+B$31 -> 250246.7 | C32: =(C$41-C$31)/(100)*($A32-$A$31)+C$31 -> 111336.23 | D32: =(D$41-D$31)/(100)*($A32-$A$31)+D$31 -> 153182.57 | E32: =(E$41-E$31)/(100)*($A32-$A$31)+E$31 -> 195167.48 | F32: =(F$41-F$31)/(100)*($A32-$A$31)+F$31 -> 70044.135 | G32: =(G$41-G$31)/(100)*($A32-$A$31)+G$31 -> 257244.19
A33: 32 | B33: =(B$41-B$31)/(100)*($A33-$A$31)+B$31 -> 251078.09 | C33: =(C$41-C$31)/(100)*($A33-$A$31)+C$31 -> 111821.2 | D33: =(D$41-D$31)/(100)*($A33-$A$31)+D$31 -> 153944.68 | E33: =(E$41-E$31)/(100)*($A33-$A$31)+E$31 -> 196345.28 | F33: =(F$41-F$31)/(100)*($A33-$A$31)+F$31 -> 70806.237 | G33: =(G$41-G$31)/(100)*($A33-$A$31)+G$31 -> 258144.85
A34: 33 | B34: =(B$41-B$31)/(100)*($A34-$A$31)+B$31 -> 251909.47 | C34: =(C$41-C$31)/(100)*($A34-$A$31)+C$31 -> 112306.17 | D34: =(D$41-D$31)/(100)*($A34-$A$31)+D$31 -> 154706.78 | E34: =(E$41-E$31)/(100)*($A34-$A$31)+E$31 -> 197523.07 | F34: =(F$41-F$31)/(100)*($A34-$A$31)+F$31 -> 71568.339 | G34: =(G$41-G$31)/(100)*($A34-$A$31)+G$31 -> 259045.52
A35: 34 | B35: =(B$41-B$31)/(100)*($A35-$A$31)+B$31 -> 252740.85 | C35: =(C$41-C$31)/(100)*($A35-$A$31)+C$31 -> 112791.15 | D35: =(D$41-D$31)/(100)*($A35-$A$31)+D$31 -> 155468.88 | E35: =(E$41-E$31)/(100)*($A35-$A$31)+E$31 -> 198700.87 | F35: =(F$41-F$31)/(100)*($A35-$A$31)+F$31 -> 72330.442 | G35: =(G$41-G$31)/(100)*($A35-$A$31)+G$31 -> 259946.19
A36: 35 | B36: =(B$41-B$31)/(100)*($A36-$A$31)+B$31 -> 253572.24 | C36: =(C$41-C$31)/(100)*($A36-$A$31)+C$31 -> 113276.12 | D36: =(D$41-D$31)/(100)*($A36-$A$31)+D$31 -> 156230.98 | E36: =(E$41-E$31)/(100)*($A36-$A$31)+E$31 -> 199878.66 | F36: =(F$41-F$31)/(100)*($A36-$A$31)+F$31 -> 73092.544 | G36: =(G$41-G$31)/(100)*($A36-$A$31)+G$31 -> 260846.85
A37: 36 | B37: =(B$41-B$31)/(100)*($A37-$A$31)+B$31 -> 254403.62 | C37: =(C$41-C$31)/(100)*($A37-$A$31)+C$31 -> 113761.1 | D37: =(D$41-D$31)/(100)*($A37-$A$31)+D$31 -> 156993.09 | E37: =(E$41-E$31)/(100)*($A37-$A$31)+E$31 -> 201056.46 | F37: =(F$41-F$31)/(100)*($A37-$A$31)+F$31 -> 73854.646 | G37: =(G$41-G$31)/(100)*($A37-$A$31)+G$31 -> 261747.52
A38: 37 | B38: =(B$41-B$31)/(100)*($A38-$A$31)+B$31 -> 255235.01 | C38: =(C$41-C$31)/(100)*($A38-$A$31)+C$31 -> 114246.07 | D38: =(D$41-D$31)/(100)*($A38-$A$31)+D$31 -> 157755.19 | E38: =(E$41-E$31)/(100)*($A38-$A$31)+E$31 -> 202234.25 | F38: =(F$41-F$31)/(100)*($A38-$A$31)+F$31 -> 74616.749 | G38: =(G$41-G$31)/(100)*($A38-$A$31)+G$31 -> 262648.18
A39: 38 | B39: =(B$41-B$31)/(100)*($A39-$A$31)+B$31 -> 256066.39 | C39: =(C$41-C$31)/(100)*($A39-$A$31)+C$31 -> 114731.05 | D39: =(D$41-D$31)/(100)*($A39-$A$31)+D$31 -> 158517.29 | E39: =(E$41-E$31)/(100)*($A39-$A$31)+E$31 -> 203412.05 | F39: =(F$41-F$31)/(100)*($A39-$A$31)+F$31 -> 75378.851 | G39: =(G$41-G$31)/(100)*($A39-$A$31)+G$31 -> 263548.85
A40: 39 | B40: =(B$41-B$31)/(100)*($A40-$A$31)+B$31 -> 256897.78 | C40: =(C$41-C$31)/(100)*($A40-$A$31)+C$31 -> 115216.02 | D40: =(D$41-D$31)/(100)*($A40-$A$31)+D$31 -> 159279.39 | E40: =(E$41-E$31)/(100)*($A40-$A$31)+E$31 -> 204589.84 | F40: =(F$41-F$31)/(100)*($A40-$A$31)+F$31 -> 76140.954 | G40: =(G$41-G$31)/(100)*($A40-$A$31)+G$31 -> 264449.52
...

Sheet max_burned_area
B1: 1 | C1: 2 | D1: 3 | E1: 4 | F1: 5 | G1: 6
A2: max | B2: 5272362.7 | C2: 5272362.7 | D2: 5272362.7 | E2: 5272362.7 | F2: 5272362.7 | G2: 5272362.7

Sheet ignition_water
B1: 1 | C1: 2 | D1: 3 | E1: 4 | F1: 5 | G1: 6
A2: 1 | B2: =2*PI()*SQRT(burned_area!B2/PI())*5 -> 3903.321 | C2: =2*PI()*SQRT(burned_area!C2/PI())*5 -> 1475.3167 | D2: =2*PI()*SQRT(burned_area!D2/PI())*5 -> 3298.9083 | E2: =2*PI()*SQRT(burned_area!E2/PI())*5 -> 1475.3167 | F2: =2*PI()*SQRT(burned_area!F2/PI())*5 -> 1475.3167 | G2: =2*PI()*SQRT(burned_area!G2/PI())*5 -> 3903.321
A3: 2 | B3: =2*PI()*SQRT(burned_area!B3/PI())*5 -> 3958.69 | C3: =2*PI()*SQRT(burned_area!C3/PI())*5 -> 1489.9968 | D3: =2*PI()*SQRT(burned_area!D3/PI())*5 -> 3325.1949 | E3: =2*PI()*SQRT(burned_area!E3/PI())*5 -> 1561.3284 | F3: =2*PI()*SQRT(burned_area!F3/PI())*5 -> 1475.3167 | G3: =2*PI()*SQRT(burned_area!G3/PI())*5 -> 3953.188
A4: 3 | B4: =2*PI()*SQRT(burned_area!B4/PI())*5 -> 3986.0861 | C4: =2*PI()*SQRT(burned_area!C4/PI())*5 -> 1497.2829 | D4: =2*PI()*SQRT(burned_area!D4/PI())*5 -> 3338.2605 | E4: =2*PI()*SQRT(burned_area!E4/PI())*5 -> 1602.6041 | F4: =2*PI()*SQRT(burned_area!F4/PI())*5 -> 1475.3167 | G4: =2*PI()*SQRT(burned_area!G4/PI())*5 -> 3977.8871
A5: 4 | B5: =2*PI()*SQRT(burned_area!B5/PI())*5 -> 4013.2952 | C5: =2*PI()*SQRT(burned_area!C5/PI())*5 -> 1504.5337 | D5: =2*PI()*SQRT(burned_area!D5/PI())*5 -> 3351.2752 | E5: =2*PI()*SQRT(burned_area!E5/PI())*5 -> 1642.8431 | F5: =2*PI()*SQRT(burned_area!F5/PI())*5 -> 1475.3167 | G5: =2*PI()*SQRT(burned_area!G5/PI())*5 -> 4002.4338
A6: 5 | B6: =2*PI()*SQRT(burned_area!B6/PI())*5 -> 4040.3211 | C6: =2*PI()*SQRT(burned_area!C6/PI())*5 -> 1511.7497 | D6: =2*PI()*SQRT(burned_area!D6/PI())*5 -> 3364.2396 | E6: =2*PI()*SQRT(burned_area!E6/PI())*5 -> 1682.1198 | F6: =2*PI()*SQRT(burned_area!F6/PI())*5 -> 1475.3167 | G6: =2*PI()*SQRT(burned_area!G6/PI())*5 -> 4026.8308
A7: 6 | B7: =2*PI()*SQRT(burned_area!B7/PI())*5 -> 4067.1673 | C7: =2*PI()*SQRT(burned_area!C7/PI())*5 -> 1518.9315 | D7: =2*PI()*SQRT(burned_area!D7/PI())*5 -> 3377.1542 | E7: =2*PI()*SQRT(burned_area!E7/PI())*5 -> 1720.5001 | F7: =2*PI()*SQRT(burned_area!F7/PI())*5 -> 1475.3167 | G7: =2*PI()*SQRT(burned_area!G7/PI())*5 -> 4051.0809
A8: 7 | B8: =2*PI()*SQRT(burned_area!B8/PI())*5 -> 4093.8376 | C8: =2*PI()*SQRT(burned_area!C8/PI())*5 -> 1526.0794 | D8: =2*PI()*SQRT(burned_area!D8/PI())*5 -> 3390.0196 | E8: =2*PI()*SQRT(burned_area!E8/PI())*5 -> 1758.0427 | F8: =2*PI()*SQRT(burned_area!F8/PI())*5 -> 1475.3167 | G8: =2*PI()*SQRT(burned_area!G8/PI())*5 -> 4075.1867
A9: 8 | B9: =2*PI()*SQRT(burned_area!B9/PI())*5 -> 4120.3352 | C9: =2*PI()*SQRT(burned_area!C9/PI())*5 -> 1533.194 | D9: =2*PI()*SQRT(burned_area!D9/PI())*5 -> 3402.8363 | E9: =2*PI()*SQRT(burned_area!E9/PI())*5 -> 1794.8002 | F9: =2*PI()*SQRT(burned_area!F9/PI())*5 -> 1475.3167 | G9: =2*PI()*SQRT(burned_area!G9/PI())*5 -> 4099.1508
A10: 9 | B10: =2*PI()*SQRT(burned_area!B10/PI())*5 -> 4146.6635 | C10: =2*PI()*SQRT(burned_area!C10/PI())*5 -> 1540.2758 | D10: =2*PI()*SQRT(burned_area!D10/PI())*5 -> 3415.605 | E10: =2*PI()*SQRT(burned_area!E10/PI())*5 -> 1830.8198 | F10: =2*PI()*SQRT(burned_area!F10/PI())*5 -> 1475.3167 | G10: =2*PI()*SQRT(burned_area!G10/PI())*5 -> 4122.9756
A11: 10 | B11: =2*PI()*SQRT(burned_area!B11/PI())*5 -> 6082.8864 | C11: =2*PI()*SQRT(burned_area!C11/PI())*5 -> 2086.4128 | D11: =2*PI()*SQRT(burned_area!D11/PI())*5 -> 4425.95 | E11: =2*PI()*SQRT(burned_area!E11/PI())*5 -> 3903.321 | F11: =2*PI()*SQRT(burned_area!F11/PI())*5 -> 1475.3167 | G11: =2*PI()*SQRT(burned_area!G11/PI())*5 -> 5901.2666
A12: 11 | B12: =2*PI()*SQRT(burned_area!B12/PI())*5 -> 6102.5346 | C12: =2*PI()*SQRT(burned_area!C12/PI())*5 -> 2112.332 | D12: =2*PI()*SQRT(burned_area!D12/PI())*5 -> 4440.6786 | E12: =2*PI()*SQRT(burned_area!E12/PI())*5 -> 3928.3336 | F12: =2*PI()*SQRT(burned_area!F12/PI())*5 -> 1489.9968 | G12: =2*PI()*SQRT(burned_area!G12/PI())*5 -> 5917.8407
A13: 12 | B13: =2*PI()*SQRT(burned_area!B13/PI())*5 -> 6122.1197 | C13: =2*PI()*SQRT(burned_area!C13/PI())*5 -> 2137.9369 | D13: =2*PI()*SQRT(burned_area!D13/PI())*5 -> 4455.3586 | E13: =2*PI()*SQRT(burned_area!E13/PI())*5 -> 3953.188 | F13: =2*PI()*SQRT(burned_area!F13/PI())*5 -> 1504.5337 | G13: =2*PI()*SQRT(burned_area!G13/PI())*5 -> 5934.3684
... A521: 520 | B521: =2*PI()*SQRT(burned_area!B521/PI())*5 -> 40698.422 | C521: =2*PI()*SQRT(burned_area!C521/PI())*5 -> 40698.422 | D521: =2*PI()*SQRT(burned_area!D521/PI())*5 -> 40698.422 | E521: =2*PI()*SQRT(burned_area!E521/PI())*5 -> 40698.422 | F521: =2*PI()*SQRT(burned_area!F521/PI())*5 -> 40698.422 | G521: =2*PI()*SQRT(burned_area!G521/PI())*5 -> 40698.422

Sheet resources_capacity
A1: Resource | B1: Capacity | C1: Base
A2: R1 | B2: 3000 | C2: Associação Humanitária de Bombeiros Voluntários de Póvoa de Lanhoso
A3: R2 | B3: 3500 | C3: Associação Humanitária de Bombeiros Voluntários de Póvoa de Lanhoso
A4: R3 | B4: 4000 | C4: Associação Humanitária de Bombeiros Voluntários de Póvoa de Lanhoso
A5: R4 | B5: 500 | C5: Associação Humanitária de Bombeiros Voluntários de Póvoa de Lanhoso
A6: R5 | B6: 600 | C6: Associação Humanitária de Bombeiros Voluntários de Póvoa de Lanhoso
