Workbook

Sheet travel_time
B1: 0 | C1: 1 | D1: 2 | E1: 3 | F1: 4 | G1: 5 | H1: 6
A2: 0 | B2: 0 | C2: 130 | D2: 340 | E2: 200 | F2: 150 | G2: 200 | H2: 130
A3: 1 | B3: 130 | C3: 0 | D3: 290 | E3: 320 | F3: 220 | G3: 270 | H3: 220
A4: 2 | B4: 340 | C4: 290 | D4: 0 | E4: 460 | F4: 220 | G4: 200 | H4: 320
A5: 3 | B5: 200 | C5: 320 | D5: 460 | E5: 0 | F5: 250 | G5: 290 | H5: 150
A6: 4 | B6: 150 | C6: 220 | D6: 220 | E6: 250 | F6: 0 | G6: 50 | H6: 100
A7: 5 | B7: 200 | C7: 270 | D7: 200 | E7: 290 | F7: 50 | G7: 0 | H7: 150
A8: 6 | B8: 130 | C8: 220 | D8: 320 | E8: 150 | F8: 100 | G8: 150 | H8: 0

Sheet travel_time_cálculo
B1: 0 | C1: 1 | D1: 2 | E1: 3 | F1: 4 | G1: 5 | H1: 6
A2: 0 | B2: =_xlfn.CEILING.MATH((B17*24)*10,10) -> 0 | C2: =_xlfn.CEILING.MATH((C17*24)*10,10) -> 130 | D2: =_xlfn.CEILING.MATH((D17*24)*10,10) -> 340 | E2: =_xlfn.CEILING.MATH((E17*24)*10,10) -> 200 | F2: =_xlfn.CEILING.MATH((F17*24)*10,10) -> 150 | G2: =_xlfn.CEILING.MATH((G17*24)*10,10) -> 200 | H2: =_xlfn.CEILING.MATH((H17*24)*10,10) -> 130
A3: 1 | B3: =_xlfn.CEILING.MATH((B18*24)*10,10) -> 130 | C3: =_xlfn.CEILING.MATH((C18*24)*10,10) -> 0 | D3: =_xlfn.CEILING.MATH((D18*24)*10,10) -> 290 | E3: =_xlfn.CEILING.MATH((E18*24)*10,10) -> 320 | F3: =_xlfn.CEILING.MATH((F18*24)*10,10) -> 220 | G3: =_xlfn.CEILING.MATH((G18*24)*10,10) -> 270 | H3: =_xlfn.CEILING.MATH((H18*24)*10,10) -> 220
A4: 2 | B4: =_xlfn.CEILING.MATH((B19*24)*10,10) -> 340 | C4: =_xlfn.CEILING.MATH((C19*24)*10,10) -> 290 | D4: =_xlfn.CEILING.MATH((D19*24)*10,10) -> 0 | E4: =_xlfn.CEILING.MATH((E19*24)*10,10) -> 460 | F4: =_xlfn.CEILING.MATH((F19*24)*10,10) -> 220 | G4: =_xlfn.CEILING.MATH((G19*24)*10,10) -> 200 | H4: =_xlfn.CEILING.MATH((H19*24)*10,10) -> 320
A5: 3 | B5: =_xlfn.CEILING.MATH((B20*24)*10,10) -> 200 | C5: =_xlfn.CEILING.MATH((C20*24)*10,10) -> 320 | D5: =_xlfn.CEILING.MATH((D20*24)*10,10) -> 460 | E5: =_xlfn.CEILING.MATH((E20*24)*10,10) -> 0 | F5: =_xlfn.CEILING.MATH((F20*24)*10,10) -> 250 | G5: =_xlfn.CEILING.MATH((G20*24)*10,10) -> 290 | H5: =_xlfn.CEILING.MATH((H20*24)*10,10) -> 150
A6: 4 | B6: =_xlfn.CEILING.MATH((B21*24)*10,10) -> 150 | C6: =_xlfn.CEILING.MATH((C21*24)*10,10) -> 220 | D6: =_xlfn.CEILING.MATH((D21*24)*10,10) -> 220 | E6: =_xlfn.CEILING.MATH((E21*24)*10,10) -> 250 | F6: =_xlfn.CEILING.MATH((F21*24)*10,10) -> 0 | G6: =_xlfn.CEILING.MATH((G21*24)*10,10) -> 50 | H6: =_xlfn.CEILING.MATH((H21*24)*10,10) -> 100
A7: 5 | B7: =_xlfn.CEILING.MATH((B22*24)*10,10) -> 200 | C7: =_xlfn.CEILING.MATH((C22*24)*10,10) -> 270 | D7: =_xlfn.CEILING.MATH((D22*24)*10,10) -> 200 | E7: =_xlfn.CEILING.MATH((E22*24)*10,10) -> 290 | F7: =_xlfn.CEILING.MATH((F22*24)*10,10) -> 50 | G7: =_xlfn.CEILING.MATH((G22*24)*10,10) -> 0 | H7: =_xlfn.CEILING.MATH((H22*24)*10,10) -> 150
A8: 6 | B8: =_xlfn.CEILING.MATH((B23*24)*10,10) -> 130 | C8: =_xlfn.CEILING.MATH((C23*24)*10,10) -> 220 | D8: =_xlfn.CEILING.MATH((D23*24)*10,10) -> 320 | E8: =_xlfn.CEILING.MATH((E23*24)*10,10) -> 150 | F8: =_xlfn.CEILING.MATH((F23*24)*10,10) -> 100 | G8: =_xlfn.CEILING.MATH((G23*24)*10,10) -> 150 | H8: =_xlfn.CEILING.MATH((H23*24)*10,10) -> 0
B16: 0 | C16: 4 | D16: 6 | E16: 7 | F16: 8 | G16: 9 | H16: 10
A17: 0 | B17: 0 | C17: 12:1 | D17: 33:38 | E17: 19:14 | F17: 14:25 | G17: 19:15 | H17: 12:2
A18: 4 | B18: 12:1 | C18: 0:0 | D18: 28:51 | E18: 31:15 | F18: 21:38 | G18: 26:27 | H18: 21:40
A19: 6 | B19: 33:38 | C19: 28:51 | D19: 0:0 | E19: 45:40 | F19: 21:38 | G19: 19:16 | H19: 31:15
A20: 7 | B20: 19:14 | C20: 31:15 | D20: 45:40 | E20: 0:0 | F20: 24:3 | G20: 28:53 | H20: 14:25
A21: 8 | B21: 14:25 | C21: 21:38 | D21: 21:38 | E21: 24:3 | F21: 0:0 | G21: 4:51 | H21: 9:38
A22: 9 | B22: 19:15 | C22: 26:27 | D22: 19:16 | E22: 28:53 | F22: 4:51 | G22: 0:0 | H22: 14:28
A23: 10 | B23: 12:2 | C23: 21:40 | D23: 31:15 | E23: 14:25 | F23: 9:38 | G23: 14:28 | H23: 0:0

Sheet burned_area_13
B1: 1 | C1: 2 | D1: 3 | E1: 4 | F1: 5 | G1: 6
A2: 10 | B2: 48497.423 | C2: 41569.219 | D2: 34641.016 | E2: 6928.2032 | F2: 6928.2032 | G2: 48497.423
A3: 20 | B3: =(B$11-B$2)/(100)*$A3+B$2 -> 62353.829 | C3: =(C$11-C$2)/(100)*$A3+C$2 -> 49883.063 | D3: =(D$11-D$2)/(100)*$A3+D$2 -> 40183.579 | E3: =(E$11-E$2)/(100)*$A3+E$2 -> 15242.047 | F3: =(F$11-F$2)/(100)*$A3+F$2 -> 6928.2032 | G3: =(G$11-G$2)/(100)*$A3+G$2 -> 60968.188
A4: 30 | B4: =(B$11-B$2)/(100)*$A4+B$2 -> 69282.032 | C4: =(C$11-C$2)/(100)*$A4+C$2 -> 54039.985 | D4: =(D$11-D$2)/(100)*$A4+D$2 -> 42954.86 | E4: =(E$11-E$2)/(100)*$A4+E$2 -> 19398.969 | F4: =(F$11-F$2)/(100)*$A4+F$2 -> 6928.2032 | G4: =(G$11-G$2)/(100)*$A4+G$2 -> 67203.571
A5: 40 | B5: =(B$11-B$2)/(100)*$A5+B$2 -> 76210.236 | C5: =(C$11-C$2)/(100)*$A5+C$2 -> 58196.907 | D5: =(D$11-D$2)/(100)*$A5+D$2 -> 45726.141 | E5: =(E$11-E$2)/(100)*$A5+E$2 -> 23555.891 | F5: =(F$11-F$2)/(100)*$A5+F$2 -> 6928.2032 | G5: =(G$11-G$2)/(100)*$A5+G$2 -> 73438.954
A6: 50 | B6: =(B$11-B$2)/(100)*$A6+B$2 -> 83138.439 | C6: =(C$11-C$2)/(100)*$A6+C$2 -> 62353.829 | D6: =(D$11-D$2)/(100)*$A6+D$2 -> 48497.423 | E6: =(E$11-E$2)/(100)*$A6+E$2 -> 27712.813 | F6: =(F$11-F$2)/(100)*$A6+F$2 -> 6928.2032 | G6: =(G$11-G$2)/(100)*$A6+G$2 -> 79674.337
A7: 60 | B7: =(B$11-B$2)/(100)*$A7+B$2 -> 90066.642 | C7: =(C$11-C$2)/(100)*$A7+C$2 -> 66510.751 | D7: =(D$11-D$2)/(100)*$A7+D$2 -> 51268.704 | E7: =(E$11-E$2)/(100)*$A7+E$2 -> 31869.735 | F7: =(F$11-F$2)/(100)*$A7+F$2 -> 6928.2032 | G7: =(G$11-G$2)/(100)*$A7+G$2 -> 85909.72
A8: 70 | B8: =(B$11-B$2)/(100)*$A8+B$2 -> 96994.845 | C8: =(C$11-C$2)/(100)*$A8+C$2 -> 70667.673 | D8: =(D$11-D$2)/(100)*$A8+D$2 -> 54039.985 | E8: =(E$11-E$2)/(100)*$A8+E$2 -> 36026.657 | F8: =(F$11-F$2)/(100)*$A8+F$2 -> 6928.2032 | G8: =(G$11-G$2)/(100)*$A8+G$2 -> 92145.103
A9: 80 | B9: =(B$11-B$2)/(100)*$A9+B$2 -> 103923.05 | C9: =(C$11-C$2)/(100)*$A9+C$2 -> 74824.595 | D9: =(D$11-D$2)/(100)*$A9+D$2 -> 56811.266 | E9: =(E$11-E$2)/(100)*$A9+E$2 -> 40183.579 | F9: =(F$11-F$2)/(100)*$A9+F$2 -> 6928.2032 | G9: =(G$11-G$2)/(100)*$A9+G$2 -> 98380.486
A10: 90 | B10: =(B$11-B$2)/(100)*$A10+B$2 -> 110851.25 | C10: =(C$11-C$2)/(100)*$A10+C$2 -> 78981.517 | D10: =(D$11-D$2)/(100)*$A10+D$2 -> 59582.548 | E10: =(E$11-E$2)/(100)*$A10+E$2 -> 44340.501 | F10: =(F$11-F$2)/(100)*$A10+F$2 -> 6928.2032 | G10: =(G$11-G$2)/(100)*$A10+G$2 -> 104615.87
A11: 100 | B11: 117779.45 | C11: 83138.439 | D11: 62353.829 | E11: 48497.423 | F11: 6928.2032 | G11: 110851.25
A12: 110 | B12: =(B$21-B$11)/(100)*($A12-$A$11)+B$11 -> 125400.48 | C12: =(C$21-C$11)/(100)*($A12-$A$11)+C$11 -> 87295.361 | D12: =(D$21-D$11)/(100)*($A12-$A$11)+D$11 -> 66510.751 | E12: =(E$21-E$11)/(100)*($A12-$A$11)+E$11 -> 54732.806 | F12: =(F$21-F$11)/(100)*($A12-$A$11)+F$11 -> 8313.8439 | G12: =(G$21-G$11)/(100)*($A12-$A$11)+G$11 -> 117086.63
A13: 120 | B13: =(B$21-B$11)/(100)*($A13-$A$11)+B$11 -> 133021.5 | C13: =(C$21-C$11)/(100)*($A13-$A$11)+C$11 -> 91452.283 | D13: =(D$21-D$11)/(100)*($A13-$A$11)+D$11 -> 70667.673 | E13: =(E$21-E$11)/(100)*($A13-$A$11)+E$11 -> 60968.188 | F13: =(F$21-F$11)/(100)*($A13-$A$11)+F$11 -> 9699.4845 | G13: =(G$21-G$11)/(100)*($A13-$A$11)+G$11 -> 123322.02
A14: 130 | B14: =(B$21-B$11)/(100)*($A14-$A$11)+B$11 -> 140642.53 | C14: =(C$21-C$11)/(100)*($A14-$A$11)+C$11 -> 95609.205 | D14: =(D$21-D$11)/(100)*($A14-$A$11)+D$11 -> 74824.595 | E14: =(E$21-E$11)/(100)*($A14-$A$11)+E$11 -> 67203.571 | F14: =(F$21-F$11)/(100)*($A14-$A$11)+F$11 -> 11085.125 | G14: =(G$21-G$11)/(100)*($A14-$A$11)+G$11 -> 129557.4
A15: 140 | B15: =(B$21-B$11)/(100)*($A15-$A$11)+B$11 -> 148263.55 | C15: =(C$21-C$11)/(100)*($A15-$A$11)+C$11 -> 99766.127 | D15: =(D$21-D$11)/(100)*($A15-$A$11)+D$11 -> 78981.517 | E15: =(E$21-E$11)/(100)*($A15-$A$11)+E$11 -> 73438.954 | F15: =(F$21-F$11)/(100)*($A15-$A$11)+F$11 -> 12470.766 | G15: =(G$21-G$11)/(100)*($A15-$A$11)+G$11 -> 135792.78
A16: 150 | B16: =(B$21-B$11)/(100)*($A16-$A$11)+B$11 -> 155884.57 | C16: =(C$21-C$11)/(100)*($A16-$A$11)+C$11 -> 103923.05 | D16: =(D$21-D$11)/(100)*($A16-$A$11)+D$11 -> 83138.439 | E16: =(E$21-E$11)/(100)*($A16-$A$11)+E$11 -> 79674.337 | F16: =(F$21-F$11)/(100)*($A16-$A$11)+F$11 -> 13856.406 | G16: =(G$21-G$11)/(100)*($A16-$A$11)+G$11 -> 142028.17
A17: 160 | B17: =(B$21-B$11)/(100)*($A17-$A$11)+B$11 -> 163505.6 | C17: =(C$21-C$11)/(100)*($A17-$A$11)+C$11 -> 108079.97 | D17: =(D$21-D$11)/(100)*($A17-$A$11)+D$11 -> 87295.361 | E17: =(E$21-E$11)/(100)*($A17-$A$11)+E$11 -> 85909.72 | F17: =(F$21-F$11)/(100)*($A17-$A$11)+F$11 -> 15242.047 | G17: =(G$21-G$11)/(100)*($A17-$A$11)+G$11 -> 148263.55
A18: 170 | B18: =(B$21-B$11)/(100)*($A18-$A$11)+B$11 -> 171126.62 | C18: =(C$21-C$11)/(100)*($A18-$A$11)+C$11 -> 112236.89 | D18: =(D$21-D$11)/(100)*($A18-$A$11)+D$11 -> 91452.283 | E18: =(E$21-E$11)/(100)*($A18-$A$11)+E$11 -> 92145.103 | F18: =(F$21-F$11)/(100)*($A18-$A$11)+F$11 -> 16627.688 | G18: =(G$21-G$11)/(100)*($A18-$A$11)+G$11 -> 154498.93
A19: 180 | B19: =(B$21-B$11)/(100)*($A19-$A$11)+B$11 -> 178747.64 | C19: =(C$21-C$11)/(100)*($A19-$A$11)+C$11 -> 116393.81 | D19: =(D$21-D$11)/(100)*($A19-$A$11)+D$11 -> 95609.205 | E19: =(E$21-E$11)/(100)*($A19-$A$11)+E$11 -> 98380.486 | F19: =(F$21-F$11)/(100)*($A19-$A$11)+F$11 -> 18013.328 | G19: =(G$21-G$11)/(100)*($A19-$A$11)+G$11 -> 160734.31
A20: 190 | B20: =(B$21-B$11)/(100)*($A20-$A$11)+B$11 -> 186368.67 | C20: =(C$21-C$11)/(100)*($A20-$A$11)+C$11 -> 120550.74 | D20: =(D$21-D$11)/(100)*($A20-$A$11)+D$11 -> 99766.127 | E20: =(E$21-E$11)/(100)*($A20-$A$11)+E$11 -> 104615.87 | F20: =(F$21-F$11)/(100)*($A20-$A$11)+F$11 -> 19398.969 | G20: =(G$21-G$11)/(100)*($A20-$A$11)+G$11 -> 166969.7
A21: 200 | B21: 193989.69 | C21: 124707.66 | D21: 103923.05 | E21: 110851.25 | F21: 20784.61 | G21: 173205.08
A22: 210 | B22: =(B$31-B$21)/(100)*($A22-$A$21)+B$21 -> 199532.25 | C22: =(C$31-C$21)/(100)*($A22-$A$21)+C$21 -> 128864.58 | D22: =(D$31-D$21)/(100)*($A22-$A$21)+D$21 -> 108772.79 | E22: =(E$31-E$21)/(100)*($A22-$A$21)+E$21 -> 119165.1 | F22: =(F$31-F$21)/(100)*($A22-$A$21)+F$21 -> 25634.352 | G22: =(G$31-G$21)/(100)*($A22-$A$21)+G$21 -> 181518.92
A23: 220 | B23: =(B$31-B$21)/(100)*($A23-$A$21)+B$21 -> 205074.82 | C23: =(C$31-C$21)/(100)*($A23-$A$21)+C$21 -> 133021.5 | D23: =(D$31-D$21)/(100)*($A23-$A$21)+D$21 -> 113622.53 | E23: =(E$31-E$21)/(100)*($A23-$A$21)+E$21 -> 127478.94 | F23: =(F$31-F$21)/(100)*($A23-$A$21)+F$21 -> 30484.094 | G23: =(G$31-G$21)/(100)*($A23-$A$21)+G$21 -> 189832.77
A24: 230 | B24: =(B$31-B$21)/(100)*($A24-$A$21)+B$21 -> 210617.38 | C24: =(C$31-C$21)/(100)*($A24-$A$21)+C$21 -> 137178.42 | D24: =(D$31-D$21)/(100)*($A24-$A$21)+D$21 -> 118472.28 | E24: =(E$31-E$21)/(100)*($A24-$A$21)+E$21 -> 135792.78 | F24: =(F$31-F$21)/(100)*($A24-$A$21)+F$21 -> 35333.836 | G24: =(G$31-G$21)/(100)*($A24-$A$21)+G$21 -> 198146.61
A25: 240 | B25: =(B$31-B$21)/(100)*($A25-$A$21)+B$21 -> 216159.94 | C25: =(C$31-C$21)/(100)*($A25-$A$21)+C$21 -> 141335.35 | D25: =(D$31-D$21)/(100)*($A25-$A$21)+D$21 -> 123322.02 | E25: =(E$31-E$21)/(100)*($A25-$A$21)+E$21 -> 144106.63 | F25: =(F$31-F$21)/(100)*($A25-$A$21)+F$21 -> 40183.579 | G25: =(G$31-G$21)/(100)*($A25-$A$21)+G$21 -> 206460.46
A26: 250 | B26: =(B$31-B$21)/(100)*($A26-$A$21)+B$21 -> 221702.5 | C26: =(C$31-C$21)/(100)*($A26-$A$21)+C$21 -> 145492.27 | D26: =(D$31-D$21)/(100)*($A26-$A$21)+D$21 -> 128171.76 | E26: =(E$31-E$21)/(100)*($A26-$A$21)+E$21 -> 152420.47 | F26: =(F$31-F$21)/(100)*($A26-$A$21)+F$21 -> 45033.321 | G26: =(G$31-G$21)/(100)*($A26-$A$21)+G$21 -> 214774.3
A27: 260 | B27: =(B$31-B$21)/(100)*($A27-$A$21)+B$21 -> 227245.07 | C27: =(C$31-C$21)/(100)*($A27-$A$21)+C$21 -> 149649.19 | D27: =(D$31-D$21)/(100)*($A27-$A$21)+D$21 -> 133021.5 | E27: =(E$31-E$21)/(100)*($A27-$A$21)+E$21 -> 160734.31 | F27: =(F$31-F$21)/(100)*($A27-$A$21)+F$21 -> 49883.063 | G27: =(G$31-G$21)/(100)*($A27-$A$21)+G$21 -> 223088.14
A28: 270 | B28: =(B$31-B$21)/(100)*($A28-$A$21)+B$21 -> 232787.63 | C28: =(C$31-C$21)/(100)*($A28-$A$21)+C$21 -> 153806.11 | D28: =(D$31-D$21)/(100)*($A28-$A$21)+D$21 -> 137871.24 | E28: =(E$31-E$21)/(100)*($A28-$A$21)+E$21 -> 169048.16 | F28: =(F$31-F$21)/(100)*($A28-$A$21)+F$21 -> 54732.806 | G28: =(G$31-G$21)/(100)*($A28-$A$21)+G$21 -> 231401.99
A29: 280 | B29: =(B$31-B$21)/(100)*($A29-$A$21)+B$21 -> 238330.19 | C29: =(C$31-C$21)/(100)*($A29-$A$21)+C$21 -> 157963.03 | D29: =(D$31-D$21)/(100)*($A29-$A$21)+D$21 -> 142720.99 | E29: =(E$31-E$21)/(100)*($A29-$A$21)+E$21 -> 177362 | F29: =(F$31-F$21)/(100)*($A29-$A$21)+F$21 -> 59582.548 | G29: =(G$31-G$21)/(100)*($A29-$A$21)+G$21 -> 239715.83
A30: 290 | B30: =(B$31-B$21)/(100)*($A30-$A$21)+B$21 -> 243872.75 | C30: =(C$31-C$21)/(100)*($A30-$A$21)+C$21 -> 162119.96 | D30: =(D$31-D$21)/(100)*($A30-$A$21)+D$21 -> 147570.73 | E30: =(E$31-E$21)/(100)*($A30-$A$21)+E$21 -> 185675.85 | F30: =(F$31-F$21)/(100)*($A30-$A$21)+F$21 -> 64432.29 | G30: =(G$31-G$21)/(100)*($A30-$A$21)+G$21 -> 248029.68
A31: 300 | B31: 249415.32 | C31: 166276.88 | D31: 152420.47 | E31: 193989.69 | F31: 69282.032 | G31: 256343.52
A32: 310 | B32: =(B$41-B$31)/(100)*($A32-$A$31)+B$31 -> 257729.16 | C32: =(C$41-C$31)/(100)*($A32-$A$31)+C$31 -> 169740.98 | D32: =(D$41-D$31)/(100)*($A32-$A$31)+D$31 -> 160041.49 | E32: =(E$41-E$31)/(100)*($A32-$A$31)+E$31 -> 205767.64 | F32: =(F$41-F$31)/(100)*($A32-$A$31)+F$31 -> 76903.056 | G32: =(G$41-G$31)/(100)*($A32-$A$31)+G$31 -> 265350.18
A33: 320 | B33: =(B$41-B$31)/(100)*($A33-$A$31)+B$31 -> 266043 | C33: =(C$41-C$31)/(100)*($A33-$A$31)+C$31 -> 173205.08 | D33: =(D$41-D$31)/(100)*($A33-$A$31)+D$31 -> 167662.52 | E33: =(E$41-E$31)/(100)*($A33-$A$31)+E$31 -> 217545.58 | F33: =(F$41-F$31)/(100)*($A33-$A$31)+F$31 -> 84524.079 | G33: =(G$41-G$31)/(100)*($A33-$A$31)+G$31 -> 274356.85
A34: 330 | B34: =(B$41-B$31)/(100)*($A34-$A$31)+B$31 -> 274356.85 | C34: =(C$41-C$31)/(100)*($A34-$A$31)+C$31 -> 176669.18 | D34: =(D$41-D$31)/(100)*($A34-$A$31)+D$31 -> 175283.54 | E34: =(E$41-E$31)/(100)*($A34-$A$31)+E$31 -> 229323.53 | F34: =(F$41-F$31)/(100)*($A34-$A$31)+F$31 -> 92145.103 | G34: =(G$41-G$31)/(100)*($A34-$A$31)+G$31 -> 283363.51
A35: 340 | B35: =(B$41-B$31)/(100)*($A35-$A$31)+B$31 -> 282670.69 | C35: =(C$41-C$31)/(100)*($A35-$A$31)+C$31 -> 180133.28 | D35: =(D$41-D$31)/(100)*($A35-$A$31)+D$31 -> 182904.57 | E35: =(E$41-E$31)/(100)*($A35-$A$31)+E$31 -> 241101.47 | F35: =(F$41-F$31)/(100)*($A35-$A$31)+F$31 -> 99766.127 | G35: =(G$41-G$31)/(100)*($A35-$A$31)+G$31 -> 292370.18
A36: 350 | B36: =(B$41-B$31)/(100)*($A36-$A$31)+B$31 -> 290984.54 | C36: =(C$41-C$31)/(100)*($A36-$A$31)+C$31 -> 183597.39 | D36: =(D$41-D$31)/(100)*($A36-$A$31)+D$31 -> 190525.59 | E36: =(E$41-E$31)/(100)*($A36-$A$31)+E$31 -> 252879.42 | F36: =(F$41-F$31)/(100)*($A36-$A$31)+F$31 -> 107387.15 | G36: =(G$41-G$31)/(100)*($A36-$A$31)+G$31 -> 301376.84
A37: 360 | B37: =(B$41-B$31)/(100)*($A37-$A$31)+B$31 -> 299298.38 | C37: =(C$41-C$31)/(100)*($A37-$A$31)+C$31 -> 187061.49 | D37: =(D$41-D$31)/(100)*($A37-$A$31)+D$31 -> 198146.61 | E37: =(E$41-E$31)/(100)*($A37-$A$31)+E$31 -> 264657.36 | F37: =(F$41-F$31)/(100)*($A37-$A$31)+F$31 -> 115008.17 | G37: =(G$41-G$31)/(100)*($A37-$A$31)+G$31 -> 310383.5
A38: 370 | B38: =(B$41-B$31)/(100)*($A38-$A$31)+B$31 -> 307612.22 | C38: =(C$41-C$31)/(100)*($A38-$A$31)+C$31 -> 190525.59 | D38: =(D$41-D$31)/(100)*($A38-$A$31)+D$31 -> 205767.64 | E38: =(E$41-E$31)/(100)*($A38-$A$31)+E$31 -> 276435.31 | F38: =(F$41-F$31)/(100)*($A38-$A$31)+F$31 -> 122629.2 | G38: =(G$41-G$31)/(100)*($A38-$A$31)+G$31 -> 319390.17
A39: 380 | B39: =(B$41-B$31)/(100)*($A39-$A$31)+B$31 -> 315926.07 | C39: =(C$41-C$31)/(100)*($A39-$A$31)+C$31 -> 193989.69 | D39: =(D$41-D$31)/(100)*($A39-$A$31)+D$31 -> 213388.66 | E39: =(E$41-E$31)/(100)*($A39-$A$31)+E$31 -> 288213.25 | F39: =(F$41-F$31)/(100)*($A39-$A$31)+F$31 -> 130250.22 | G39: =(G$41-G$31)/(100)*($A39-$A$31)+G$31 -> 328396.83
A40: 390 | B40: =(B$41-B$31)/(100)*($A40-$A$31)+B$31 -> 324239.91 | C40: =(C$41-C$31)/(100)*($A40-$A$31)+C$31 -> 197453.79 | D40: =(D$41-D$31)/(100)*($A40-$A$31)+D$31 -> 221009.68 | E40: =(E$41-E$31)/(100)*($A40-$A$31)+E$31 -> 299991.2 | F40: =(F$41-F$31)/(100)*($A40-$A$31)+F$31 -> 137871.24 | G40: =(G$41-G$31)/(100)*($A40-$A$31)+G$31 -> 337403.5
...

Sheet burned_area
B1: 1 | C1: 2 | D1: 3 | E1: 4 | F1: 5 | G1: 6
A2: 10 | B2: 48497.423 | C2: 6928.2032 | D2: 34641.016 | E2: 6928.2032 | F2: 6928.2032 | G2: 48497.423
A3: 20 | B3: =(B$11-B$2)/(100)*$A3+B$2 -> 62353.829 | C3: =(C$11-C$2)/(100)*$A3+C$2 -> 8313.8439 | D3: =(D$11-D$2)/(100)*$A3+D$2 -> 40183.579 | E3: =(E$11-E$2)/(100)*$A3+E$2 -> 15242.047 | F3: =(F$11-F$2)/(100)*$A3+F$2 -> 6928.2032 | G3: =(G$11-G$2)/(100)*$A3+G$2 -> 60968.188
A4: 30 | B4: =(B$11-B$2)/(100)*$A4+B$2 -> 69282.032 | C4: =(C$11-C$2)/(100)*$A4+C$2 -> 9006.6642 | D4: =(D$11-D$2)/(100)*$A4+D$2 -> 42954.86 | E4: =(E$11-E$2)/(100)*$A4+E$2 -> 19398.969 | F4: =(F$11-F$2)/(100)*$A4+F$2 -> 6928.2032 | G4: =(G$11-G$2)/(100)*$A4+G$2 -> 67203.571
A5: 40 | B5: =(B$11-B$2)/(100)*$A5+B$2 -> 76210.236 | C5: =(C$11-C$2)/(100)*$A5+C$2 -> 9699.4845 | D5: =(D$11-D$2)/(100)*$A5+D$2 -> 45726.141 | E5: =(E$11-E$2)/(100)*$A5+E$2 -> 23555.891 | F5: =(F$11-F$2)/(100)*$A5+F$2 -> 6928.2032 | G5: =(G$11-G$2)/(100)*$A5+G$2 -> 73438.954
A6: 50 | B6: =(B$11-B$2)/(100)*$A6+B$2 -> 83138.439 | C6: =(C$11-C$2)/(100)*$A6+C$2 -> 10392.305 | D6: =(D$11-D$2)/(100)*$A6+D$2 -> 48497.423 | E6: =(E$11-E$2)/(100)*$A6+E$2 -> 27712.813 | F6: =(F$11-F$2)/(100)*$A6+F$2 -> 6928.2032 | G6: =(G$11-G$2)/(100)*$A6+G$2 -> 79674.337
A7: 60 | B7: =(B$11-B$2)/(100)*$A7+B$2 -> 90066.642 | C7: =(C$11-C$2)/(100)*$A7+C$2 -> 11085.125 | D7: =(D$11-D$2)/(100)*$A7+D$2 -> 51268.704 | E7: =(E$11-E$2)/(100)*$A7+E$2 -> 31869.735 | F7: =(F$11-F$2)/(100)*$A7+F$2 -> 6928.2032 | G7: =(G$11-G$2)/(100)*$A7+G$2 -> 85909.72
A8: 70 | B8: =(B$11-B$2)/(100)*$A8+B$2 -> 96994.845 | C8: =(C$11-C$2)/(100)*$A8+C$2 -> 11777.945 | D8: =(D$11-D$2)/(100)*$A8+D$2 -> 54039.985 | E8: =(E$11-E$2)/(100)*$A8+E$2 -> 36026.657 | F8: =(F$11-F$2)/(100)*$A8+F$2 -> 6928.2032 | G8: =(G$11-G$2)/(100)*$A8+G$2 -> 92145.103
A9: 80 | B9: =(B$11-B$2)/(100)*$A9+B$2 -> 103923.05 | C9: =(C$11-C$2)/(100)*$A9+C$2 -> 12470.766 | D9: =(D$11-D$2)/(100)*$A9+D$2 -> 56811.266 | E9: =(E$11-E$2)/(100)*$A9+E$2 -> 40183.579 | F9: =(F$11-F$2)/(100)*$A9+F$2 -> 6928.2032 | G9: =(G$11-G$2)/(100)*$A9+G$2 -> 98380.486
A10: 90 | B10: =(B$11-B$2)/(100)*$A10+B$2 -> 110851.25 | C10: =(C$11-C$2)/(100)*$A10+C$2 -> 13163.586 | D10: =(D$11-D$2)/(100)*$A10+D$2 -> 59582.548 | E10: =(E$11-E$2)/(100)*$A10+E$2 -> 44340.501 | F10: =(F$11-F$2)/(100)*$A10+F$2 -> 6928.2032 | G10: =(G$11-G$2)/(100)*$A10+G$2 -> 104615.87
A11: 100 | B11: 117779.45 | C11: 13856.406 | D11: 62353.829 | E11: 48497.423 | F11: 6928.2032 | G11: 110851.25
A12: 110 | B12: =(B$21-B$11)/(100)*($A12-$A$11)+B$11 -> 125400.48 | C12: =(C$21-C$11)/(100)*($A12-$A$11)+C$11 -> 17320.508 | D12: =(D$21-D$11)/(100)*($A12-$A$11)+D$11 -> 66510.751 | E12: =(E$21-E$11)/(100)*($A12-$A$11)+E$11 -> 54732.806 | F12: =(F$21-F$11)/(100)*($A12-$A$11)+F$11 -> 8313.8439 | G12: =(G$21-G$11)/(100)*($A12-$A$11)+G$11 -> 117086.63
A13: 120 | B13: =(B$21-B$11)/(100)*($A13-$A$11)+B$11 -> 133021.5 | C13: =(C$21-C$11)/(100)*($A13-$A$11)+C$11 -> 20784.61 | D13: =(D$21-D$11)/(100)*($A13-$A$11)+D$11 -> 70667.673 | E13: =(E$21-E$11)/(100)*($A13-$A$11)+E$11 -> 60968.188 | F13: =(F$21-F$11)/(100)*($A13-$A$11)+F$11 -> 9699.4845 | G13: =(G$21-G$11)/(100)*($A13-$A$11)+G$11 -> 123322.02
A14: 130 | B14: =(B$21-B$11)/(100)*($A14-$A$11)+B$11 -> 140642.53 | C14: =(C$21-C$11)/(100)*($A14-$A$11)+C$11 -> 24248.711 | D14: =(D$21-D$11)/(100)*($A14-$A$11)+D$11 -> 74824.595 | E14: =(E$21-E$11)/(100)*($A14-$A$11)+E$11 -> 67203.571 | F14: =(F$21-F$11)/(100)*($A14-$A$11)+F$11 -> 11085.125 | G14: =(G$21-G$11)/(100)*($A14-$A$11)+G$11 -> 129557.4
A15: 140 | B15: =(B$21-B$11)/(100)*($A15-$A$11)+B$11 -> 148263.55 | C15: =(C$21-C$11)/(100)*($A15-$A$11)+C$11 -> 27712.813 | D15: =(D$21-D$11)/(100)*($A15-$A$11)+D$11 -> 78981.517 | E15: =(E$21-E$11)/(100)*($A15-$A$11)+E$11 -> 73438.954 | F15: =(F$21-F$11)/(100)*($A15-$A$11)+F$11 -> 12470.766 | G15: =(G$21-G$11)/(100)*($A15-$A$11)+G$11 -> 135792.78
A16: 150 | B16: =(B$21-B$11)/(100)*($A16-$A$11)+B$11 -> 155884.57 | C16: =(C$21-C$11)/(100)*($A16-$A$11)+C$11 -> 31176.915 | D16: =(D$21-D$11)/(100)*($A16-$A$11)+D$11 -> 83138.439 | E16: =(E$21-E$11)/(100)*($A16-$A$11)+E$11 -> 79674.337 | F16: =(F$21-F$11)/(100)*($A16-$A$11)+F$11 -> 13856.406 | G16: =(G$21-G$11)/(100)*($A16-$A$11)+G$11 -> 142028.17
A17: 160 | B17: =(B$21-B$11)/(100)*($A17-$A$11)+B$11 -> 163505.6 | C17: =(C$21-C$11)/(100)*($A17-$A$11)+C$11 -> 34641.016 | D17: =(D$21-D$11)/(100)*($A17-$A$11)+D$11 -> 87295.361 | E17: =(E$21-E$11)/(100)*($A17-$A$11)+E$11 -> 85909.72 | F17: =(F$21-F$11)/(100)*($A17-$A$11)+F$11 -> 15242.047 | G17: =(G$21-G$11)/(100)*($A17-$A$11)+G$11 -> 148263.55
A18: 170 | B18: =(B$21-B$11)/(100)*($A18-$A$11)+B$11 -> 171126.62 | C18: =(C$21-C$11)/(100)*($A18-$A$11)+C$11 -> 38105.118 | D18: =(D$21-D$11)/(100)*($A18-$A$11)+D$11 -> 91452.283 | E18: =(E$21-E$11)/(100)*($A18-$A$11)+E$11 -> 92145.103 | F18: =(F$21-F$11)/(100)*($A18-$A$11)+F$11 -> 16627.688 | G18: =(G$21-G$11)/(100)*($A18-$A$11)+G$11 -> 154498.93
A19: 180 | B19: =(B$21-B$11)/(100)*($A19-$A$11)+B$11 -> 178747.64 | C19: =(C$21-C$11)/(100)*($A19-$A$11)+C$11 -> 41569.219 | D19: =(D$21-D$11)/(100)*($A19-$A$11)+D$11 -> 95609.205 | E19: =(E$21-E$11)/(100)*($A19-$A$11)+E$11 -> 98380.486 | F19: =(F$21-F$11)/(100)*($A19-$A$11)+F$11 -> 18013.328 | G19: =(G$21-G$11)/(100)*($A19-$A$11)+G$11 -> 160734.31
A20: 190 | B20: =(B$21-B$11)/(100)*($A20-$A$11)+B$11 -> 186368.67 | C20: =(C$21-C$11)/(100)*($A20-$A$11)+C$11 -> 45033.321 | D20: =(D$21-D$11)/(100)*($A20-$A$11)+D$11 -> 99766.127 | E20: =(E$21-E$11)/(100)*($A20-$A$11)+E$11 -> 104615.87 | F20: =(F$21-F$11)/(100)*($A20-$A$11)+F$11 -> 19398.969 | G20: =(G$21-G$11)/(100)*($A20-$A$11)+G$11 -> 166969.7
A21: 200 | B21: 193989.69 | C21: 48497.423 | D21: 103923.05 | E21: 110851.25 | F21: 20784.61 | G21: 173205.08
A22: 210 | B22: =(B$31-B$21)/(100)*($A22-$A$21)+B$21 -> 199532.25 | C22: =(C$31-C$21)/(100)*($A22-$A$21)+C$21 -> 54732.806 | D22: =(D$31-D$21)/(100)*($A22-$A$21)+D$21 -> 108772.79 | E22: =(E$31-E$21)/(100)*($A22-$A$21)+E$21 -> 119165.1 | F22: =(F$31-F$21)/(100)*($A22-$A$21)+F$21 -> 25634.352 | G22: =(G$31-G$21)/(100)*($A22-$A$21)+G$21 -> 181518.92
A23: 220 | B23: =(B$31-B$21)/(100)*($A23-$A$21)+B$21 -> 205074.82 | C23: =(C$31-C$21)/(100)*($A23-$A$21)+C$21 -> 60968.188 | D23: =(D$31-D$21)/(100)*($A23-$A$21)+D$21 -> 113622.53 | E23: =(E$31-E$21)/(100)*($A23-$A$21)+E$21 -> 127478.94 | F23: =(F$31-F$21)/(100)*($A23-$A$21)+F$21 -> 30484.094 | G23: =(G$31-G$21)/(100)*($A23-$A$21)+G$21 -> 189832.77
A24: 230 | B24: =(B$31-B$21)/(100)*($A24-$A$21)+B$21 -> 210617.38 | C24: =(C$31-C$21)/(100)*($A24-$A$21)+C$21 -> 67203.571 | D24: =(D$31-D$21)/(100)*($A24-$A$21)+D$21 -> 118472.28 | E24: =(E$31-E$21)/(100)*($A24-$A$21)+E$21 -> 135792.78 | F24: =(F$31-F$21)/(100)*($A24-$A$21)+F$21 -> 35333.836 | G24: =(G$31-G$21)/(100)*($A24-$A$21)+G$21 -> 198146.61
A25: 240 | B25: =(B$31-B$21)/(100)*($A25-$A$21)+B$21 -> 216159.94 | C25: =(C$31-C$21)/(100)*($A25-$A$21)+C$21 -> 73438.954 | D25: =(D$31-D$21)/(100)*($A25-$A$21)+D$21 -> 123322.02 | E25: =(E$31-E$21)/(100)*($A25-$A$21)+E$21 -> 144106.63 | F25: =(F$31-F$21)/(100)*($A25-$A$21)+F$21 -> 40183.579 | G25: =(G$31-G$21)/(100)*($A25-$A$21)+G$21 -> 206460.46
A26: 250 | B26: =(B$31-B$21)/(100)*($A26-$A$21)+B$21 -> 221702.5 | C26: =(C$31-C$21)/(100)*($A26-$A$21)+C$21 -> 79674.337 | D26: =(D$31-D$21)/(100)*($A26-$A$21)+D$21 -> 128171.76 | E26: =(E$31-E$21)/(100)*($A26-$A$21)+E$21 -> 152420.47 | F26: =(F$31-F$21)/(100)*($A26-$A$21)+F$21 -> 45033.321 | G26: =(G$31-G$21)/(100)*($A26-$A$21)+G$21 -> 214774.3
A27: 260 | B27: =(B$31-B$21)/(100)*($A27-$A$21)+B$21 -> 227245.07 | C27: =(C$31-C$21)/(100)*($A27-$A$21)+C$21 -> 85909.72 | D27: =(D$31-D$21)/(100)*($A27-$A$21)+D$21 -> 133021.5 | E27: =(E$31-E$21)/(100)*($A27-$A$21)+E$21 -> 160734.31 | F27: =(F$31-F$21)/(100)*($A27-$A$21)+F$21 -> 49883.063 | G27: =(G$31-G$21)/(100)*($A27-$A$21)+G$21 -> 223088.14
A28: 270 | B28: =(B$31-B$21)/(100)*($A28-$A$21)+B$21 -> 232787.63 | C28: =(C$31-C$21)/(100)*($A28-$A$21)+C$21 -> 92145.103 | D28: =(D$31-D$21)/(100)*($A28-$A$21)+D$21 -> 137871.24 | E28: =(E$31-E$21)/(100)*($A28-$A$21)+E$21 -> 169048.16 | F28: =(F$31-F$21)/(100)*($A28-$A$21)+F$21 -> 54732.806 | G28: =(G$31-G$21)/(100)*($A28-$A$21)+G$21 -> 231401.99
A29: 280 | B29: =(B$31-B$21)/(100)*($A29-$A$21)+B$21 -> 238330.19 | C29: =(C$31-C$21)/(100)*($A29-$A$21)+C$21 -> 98380.486 | D29: =(D$31-D$21)/(100)*($A29-$A$21)+D$21 -> 142720.99 | E29: =(E$31-E$21)/(100)*($A29-$A$21)+E$21 -> 177362 | F29: =(F$31-F$21)/(100)*($A29-$A$21)+F$21 -> 59582.548 | G29: =(G$31-G$21)/(100)*($A29-$A$21)+G$21 -> 239715.83
A30: 290 | B30: =(B$31-B$21)/(100)*($A30-$A$21)+B$21 -> 243872.75 | C30: =(C$31-C$21)/(100)*($A30-$A$21)+C$21 -> 104615.87 | D30: =(D$31-D$21)/(100)*($A30-$A$21)+D$21 -> 147570.73 | E30: =(E$31-E$21)/(100)*($A30-$A$21)+E$21 -> 185675.85 | F30: =(F$31-F$21)/(100)*($A30-$A$21)+F$21 -> 64432.29 | G30: =(G$31-G$21)/(100)*($A30-$A$21)+G$21 -> 248029.68
A31: 300 | B31: 249415.32 | C31: 110851.25 | D31: 152420.47 | E31: 193989.69 | F31: 69282.032 | G31: 256343.52
A32: 310 | B32: =(B$41-B$31)/(100)*($A32-$A$31)+B$31 -> 257729.16 | C32: =(C$41-C$31)/(100)*($A32-$A$31)+C$31 -> 115700.99 | D32: =(D$41-D$31)/(100)*($A32-$A$31)+D$31 -> 160041.49 | E32: =(E$41-E$31)/(100)*($A32-$A$31)+E$31 -> 205767.64 | F32: =(F$41-F$31)/(100)*($A32-$A$31)+F$31 -> 76903.056 | G32: =(G$41-G$31)/(100)*($A32-$A$31)+G$31 -> 265350.18
A33: 320 | B33: =(B$41-B$31)/(100)*($A33-$A$31)+B$31 -> 266043 | C33: =(C$41-C$31)/(100)*($A33-$A$31)+C$31 -> 120550.74 | D33: =(D$41-D$31)/(100)*($A33-$A$31)+D$31 -> 167662.52 | E33: =(E$41-E$31)/(100)*($A33-$A$31)+E$31 -> 217545.58 | F33: =(F$41-F$31)/(100)*($A33-$A$31)+F$31 -> 84524.079 | G33: =(G$41-G$31)/(100)*($A33-$A$31)+G$31 -> 274356.85
A34: 330 | B34: =(B$41-B$31)/(100)*($A34-$A$31)+B$31 -> 274356.85 | C34: =(C$41-C$31)/(100)*($A34-$A$31)+C$31 -> 125400.48 | D34: =(D$41-D$31)/(100)*($A34-$A$31)+D$31 -> 175283.54 | E34: =(E$41-E$31)/(100)*($A34-$A$31)+E$31 -> 229323.53 | F34: =(F$41-F$31)/(100)*($A34-$A$31)+F$31 -> 92145.103 | G34: =(G$41-G$31)/(100)*($A34-$A$31)+G$31 -> 283363.51
A35: 340 | B35: =(B$41-B$31)/(100)*($A35-$A$31)+B$31 -> 282670.69 | C35: =(C$41-C$31)/(100)*($A35-$A$31)+C$31 -> 130250.22 | D35: =(D$41-D$31)/(100)*($A35-$A$31)+D$31 -> 182904.57 | E35: =(E$41-E$31)/(100)*($A35-$A$31)+E$31 -> 241101.47 | F35: =(F$41-F$31)/(100)*($A35-$A$31)+F$31 -> 99766.127 | G35: =(G$41-G$31)/(100)*($A35-$A$31)+G$31 -> 292370.18
A36: 350 | B36: =(B$41-B$31)/(100)*($A36-$A$31)+B$31 -> 290984.54 | C36: =(C$41-C$31)/(100)*($A36-$A$31)+C$31 -> 135099.96 | D36: =(D$41-D$31)/(100)*($A36-$A$31)+D$31 -> 190525.59 | E36: =(E$41-E$31)/(100)*($A36-$A$31)+E$31 -> 252879.42 | F36: =(F$41-F$31)/(100)*($A36-$A$31)+F$31 -> 107387.15 | G36: =(G$41-G$31)/(100)*($A36-$A$31)+G$31 -> 301376.84
A37: 360 | B37: =(B$41-B$31)/(100)*($A37-$A$31)+B$31 -> 299298.38 | C37: =(C$41-C$31)/(100)*($A37-$A$31)+C$31 -> 139949.71 | D37: =(D$41-D$31)/(100)*($A37-$A$31)+D$31 -> 198146.61 | E37: =(E$41-E$31)/(100)*($A37-$A$31)+E$31 -> 264657.36 | F37: =(F$41-F$31)/(100)*($A37-$A$31)+F$31 -> 115008.17 | G37: =(G$41-G$31)/(100)*($A37-$A$31)+G$31 -> 310383.5
A38: 370 | B38: =(B$41-B$31)/(100)*($A38-$A$31)+B$31 -> 307612.22 | C38: =(C$41-C$31)/(100)*($A38-$A$31)+C$31 -> 144799.45 | D38: =(D$41-D$31)/(100)*($A38-$A$31)+D$31 -> 205767.64 | E38: =(E$41-E$31)/(100)*($A38-$A$31)+E$31 -> 276435.31 | F38: =(F$41-F$31)/(100)*($A38-$A$31)+F$31 -> 122629.2 | G38: =(G$41-G$31)/(100)*($A38-$A$31)+G$31 -> 319390.17
A39: 380 | B39: =(B$41-B$31)/(100)*($A39-$A$31)+B$31 -> 315926.07 | C39: =(C$41-C$31)/(100)*($A39-$A$31)+C$31 -> 149649.19 | D39: =(D$41-D$31)/(100)*($A39-$A$31)+D$31 -> 213388.66 | E39: =(E$41-E$31)/(100)*($A39-$A$31)+E$31 -> 288213.25 | F39: =(F$41-F$31)/(100)*($A39-$A$31)+F$31 -> 130250.22 | G39: =(G$41-G$31)/(100)*($A39-$A$31)+G$31 -> 328396.83
A40: 390 | B40: =(B$41-B$31)/(100)*($A40-$A$31)+B$31 -> 324239.91 | C40: =(C$41-C$31)/(100)*($A40-$A$31)+C$31 -> 154498.93 | D40: =(D$41-D$31)/(100)*($A40-$A$31)+D$31 -> 221009.68 | E40: =(E$41-E$31)/(100)*($A40-$A$31)+E$31 -> 299991.2 | F40: =(F$41-F$31)/(100)*($A40-$A$31)+F$31 -> 137871.24 | G40: =(G$41-G$31)/(100)*($A40-$A$31)+G$31 -> 337403.5
...

Sheet max_burned_area
B1: 1 | C1: 2 | D1: 3 | E1: 4 | F1: 5 | G1: 6
A2: max | B2: 5272362.7 | C2: 5272362.7 | D2: 5272362.7 | E2: 5272362.7 | F2: 5272362.7 | G2: 5272362.7

Sheet ignition_water
B1: 1 | C1: 2 | D1: 3 | E1: 4 | F1: 5 | G1: 6
A2: 10 | B2: =2*PI()*SQRT(burned_area!B2/PI())*5 -> 3903.321 | C2: =2*PI()*SQRT(burned_area!C2/PI())*5 -> 1475.3167 | D2: =2*PI()*SQRT(burned_area!D2/PI())*5 -> 3298.9083 | E2: =2*PI()*SQRT(burned_area!E2/PI())*5 -> 1475.3167 | F2: =2*PI()*SQRT(burned_area!F2/PI())*5 -> 1475.3167 | G2: =2*PI()*SQRT(burned_area!G2/PI())*5 -> 3903.321
A3: 20 | B3: =2*PI()*SQRT(burned_area!B3/PI())*5 -> 4425.95 | C3: =2*PI()*SQRT(burned_area!C3/PI())*5 -> 1616.1284 | D3: =2*PI()*SQRT(burned_area!D3/PI())*5 -> 3553.033 | E3: =2*PI()*SQRT(burned_area!E3/PI())*5 -> 2188.2482 | F3: =2*PI()*SQRT(burned_area!F3/PI())*5 -> 1475.3167 | G3: =2*PI()*SQRT(burned_area!G3/PI())*5 -> 4376.4965
A4: 30 | B4: =2*PI()*SQRT(burned_area!B4/PI())*5 -> 4665.3609 | C4: =2*PI()*SQRT(burned_area!C4/PI())*5 -> 1682.1198 | D4: =2*PI()*SQRT(burned_area!D4/PI())*5 -> 3673.5088 | E4: =2*PI()*SQRT(burned_area!E4/PI())*5 -> 2468.6769 | F4: =2*PI()*SQRT(burned_area!F4/PI())*5 -> 1475.3167 | G4: =2*PI()*SQRT(burned_area!G4/PI())*5 -> 4594.8476
A5: 40 | B5: =2*PI()*SQRT(burned_area!B5/PI())*5 -> 4893.0718 | C5: =2*PI()*SQRT(burned_area!C5/PI())*5 -> 1745.6182 | D5: =2*PI()*SQRT(burned_area!D5/PI())*5 -> 3790.1571 | E5: =2*PI()*SQRT(burned_area!E5/PI())*5 -> 2720.3495 | F5: =2*PI()*SQRT(burned_area!F5/PI())*5 -> 1475.3167 | G5: =2*PI()*SQRT(burned_area!G5/PI())*5 -> 4803.283
A6: 50 | B6: =2*PI()*SQRT(burned_area!B6/PI())*5 -> 5110.6468 | C6: =2*PI()*SQRT(burned_area!C6/PI())*5 -> 1806.8865 | D6: =2*PI()*SQRT(burned_area!D6/PI())*5 -> 3903.321 | E6: =2*PI()*SQRT(burned_area!E6/PI())*5 -> 2950.6333 | F6: =2*PI()*SQRT(burned_area!F6/PI())*5 -> 1475.3167 | G6: =2*PI()*SQRT(burned_area!G6/PI())*5 -> 5003.0422
A7: 60 | B7: =2*PI()*SQRT(burned_area!B7/PI())*5 -> 5319.3299 | C7: =2*PI()*SQRT(burned_area!C7/PI())*5 -> 1866.1444 | D7: =2*PI()*SQRT(burned_area!D7/PI())*5 -> 4013.2952 | E7: =2*PI()*SQRT(burned_area!E7/PI())*5 -> 3164.2017 | F7: =2*PI()*SQRT(burned_area!F7/PI())*5 -> 1475.3167 | G7: =2*PI()*SQRT(burned_area!G7/PI())*5 -> 5195.126
A8: 70 | B8: =2*PI()*SQRT(burned_area!B8/PI())*5 -> 5520.1295 | C8: =2*PI()*SQRT(burned_area!C8/PI())*5 -> 1923.5776 | D8: =2*PI()*SQRT(burned_area!D8/PI())*5 -> 4120.3352 | E8: =2*PI()*SQRT(burned_area!E8/PI())*5 -> 3364.2396 | F8: =2*PI()*SQRT(burned_area!F8/PI())*5 -> 1475.3167 | G8: =2*PI()*SQRT(burned_area!G8/PI())*5 -> 5380.3567
A9: 80 | B9: =2*PI()*SQRT(burned_area!B9/PI())*5 -> 5713.8768 | C9: =2*PI()*SQRT(burned_area!C9/PI())*5 -> 1979.345 | D9: =2*PI()*SQRT(burned_area!D9/PI())*5 -> 4224.664 | E9: =2*PI()*SQRT(burned_area!E9/PI())*5 -> 3553.033 | F9: =2*PI()*SQRT(burned_area!F9/PI())*5 -> 1475.3167 | G9: =2*PI()*SQRT(burned_area!G9/PI())*5 -> 5559.4191
A10: 90 | B10: =2*PI()*SQRT(burned_area!B10/PI())*5 -> 5901.2666 | C10: =2*PI()*SQRT(burned_area!C10/PI())*5 -> 2033.5837 | D10: =2*PI()*SQRT(burned_area!D10/PI())*5 -> 4326.4777 | E10: =2*PI()*SQRT(burned_area!E10/PI())*5 -> 3732.2887 | F10: =2*PI()*SQRT(burned_area!F10/PI())*5 -> 1475.3167 | G10: =2*PI()*SQRT(burned_area!G10/PI())*5 -> 5732.8915
A11: 100 | B11: =2*PI()*SQRT(burned_area!B11/PI())*5 -> 6082.8864 | C11: =2*PI()*SQRT(burned_area!C11/PI())*5 -> 2086.4128 | D11: =2*PI()*SQRT(burned_area!D11/PI())*5 -> 4425.95 | E11: =2*PI()*SQRT(burned_area!E11/PI())*5 -> 3903.321 | F11: =2*PI()*SQRT(burned_area!F11/PI())*5 -> 1475.3167 | G11: =2*PI()*SQRT(burned_area!G11/PI())*5 -> 5901.2666
A12: 110 | B12: =2*PI()*SQRT(burned_area!B12/PI())*5 -> 6276.6012 | C12: =2*PI()*SQRT(burned_area!C12/PI())*5 -> 2332.6805 | D12: =2*PI()*SQRT(burned_area!D12/PI())*5 -> 4571.1015 | E12: =2*PI()*SQRT(burned_area!E12/PI())*5 -> 4146.6635 | F12: =2*PI()*SQRT(burned_area!F12/PI())*5 -> 1616.1284 | G12: =2*PI()*SQRT(burned_area!G12/PI())*5 -> 6064.9692
A13: 120 | B13: =2*PI()*SQRT(burned_area!B13/PI())*5 -> 6464.5137 | C13: =2*PI()*SQRT(burned_area!C13/PI())*5 -> 2555.3234 | D13: =2*PI()*SQRT(burned_area!D13/PI())*5 -> 4711.7835 | E13: =2*PI()*SQRT(burned_area!E13/PI())*5 -> 4376.4965 | F13: =2*PI()*SQRT(burned_area!F13/PI())*5 -> 1745.6182 | G13: =2*PI()*SQRT(burned_area!G13/PI())*5 -> 6224.3678
... A521: 5200 | B521: =2*PI()*SQRT(burned_area!B521/PI())*5 -> 40698.422 | C521: =2*PI()*SQRT(burned_area!C521/PI())*5 -> 40698.422 | D521: =2*PI()*SQRT(burned_area!D521/PI())*5 -> 40698.422 | E521: =2*PI()*SQRT(burned_area!E521/PI())*5 -> 40698.422 | F521: =2*PI()*SQRT(burned_area!F521/PI())*5 -> 40698.422 | G521: =2*PI()*SQRT(burned_area!G521/PI())*5 -> 40698.422

Sheet resources_capacity
A1: Resource | B1: Capacity | C1: Base
A2: R1 | B2: 3000 | C2: Associação Humanitária de Bombeiros Voluntários de Póvoa de Lanhoso
A3: R2 | B3: 3500 | C3: Associação Humanitária de Bombeiros Voluntários de Póvoa de Lanhoso
A4: R3 | B4: 4000 | C4: Associação Humanitária de Bombeiros Voluntários de Póvoa de Lanhoso
A5: R4 | B5: 500 | C5: Associação Humanitária de Bombeiros Voluntários de Póvoa de Lanhoso
A6: R5 | B6: 600 | C6: Associação Humanitária de Bombeiros Voluntários de Póvoa de Lanhoso
